<?xml version="1.0"?>

<robot name="kobuki_v1">

    <link name="base_footprint"/> <!-- base_footprint marco de referencia inercial-->

    <joint name="fixed_joint" type="fixed">
        <origin xyz="0.0 0.0 0.0102" rpy="0.0 0.0 0.0"/>
        <parent link="base_footprint"/>
        <child link="base_link"/>
    </joint>

    <link name="base_link">
        <visual>
            <origin xyz="0.0 0.0 0.05949"/>
            <geometry>
                <cylinder length="0.10938" radius="0.178"/>
            </geometry>
            <material name="Red">
                <color rgba="1.0 0.0 0.0 1.0"/>
            </material>
        </visual>
        <collision>
            <origin xyz="0.0 0.0 0.05949"/>
            <geometry>
                <cylinder length="0.10938" radius="0.178"/>
            </geometry>
        </collision>
        <inertial>
            <mass value="1.0"/>
            <inertia ixx="0.001" ixy="0.0" ixz="0.0" iyy="0.001" iyz="0.0" izz="0.001"/>
        </inertial>
    </link>

    <joint name="sphere_joint1" type="fixed">
        <origin xyz="0.115 0.0 0.007" rpy="0.0 0.0 0.0"/>
        <parent link="base_link"/>
        <child link="sphere_link1"/>
    </joint>

    <link name="sphere_link1">
        <visual>
            <origin xyz="0.0 0.0 0.0"/>
            <geometry>
                <sphere radius="0.017"/>
            </geometry>
            <material name="Blue">
                <color rgba="0.0 0.0 1.0 1.0"/>
            </material>
        </visual>
        <collision>
            <origin xyz="0.0 0.0 0.0"/>
            <geometry>
                <sphere radius="0.017"/>
            </geometry>
        </collision>
        <inertial>
            <mass value="1.0"/>
            <inertia ixx="0.001" ixy="0.0" ixz="0.0" iyy="0.001" iyz="0.0" izz="0.001"/>
        </inertial>
    </link>

    <joint name="sphere_joint2" type="fixed">
        <origin xyz="-0.115 0.0 0.009" rpy="0.0 0.0 0.0"/>
        <parent link="base_link"/>
        <child link="sphere_link2"/>
    </joint>

    <link name="sphere_link2">
        <visual>
            <origin xyz="0.0 0.0 0.0"/>
            <geometry>
                <sphere radius="0.017"/>
            </geometry>
            <material name="Blue">
                <color rgba="0.0 0.0 1.0 1.0"/>
            </material>
        </visual>
        <collision>
            <origin xyz="0.0 0.0 0.0"/>
            <geometry>
                <sphere radius="0.017"/>
            </geometry>
        </collision>
        <inertial>
            <mass value="1.0"/>
            <inertia ixx="0.001" ixy="0.0" ixz="0.0" iyy="0.001" iyz="0.0" izz="0.001"/>
        </inertial>
    </link>

    <joint name="joint_left" type="continuous">
        <origin xyz="0.0 0.115 0.0250" rpy="-1.5707 0.0 0.0"/>
        <parent link="base_link"/>
        <child link="left_wheel"/>
        <axis xyz="0.0 0.0 1.0"/>
        <limit effort="20" velocity="20.0"/>
    </joint>

    <link name="left_wheel">
        <visual>
            <origin xyz="0.0 0.0 0.0"/>
            <geometry>
                <cylinder length="0.0206" radius="0.035"/>
            </geometry>
            <material name="Green">
                <color rgba="0.0 1.0 0.0 1.0"/>
            </material>
        </visual>
        <collision>
            <origin xyz="0.0 0.0 0.0"/>
            <geometry>
                <cylinder length="0.0206" radius="0.035"/>
            </geometry>
        </collision>
        <inertial>
            <mass value="1.0"/>
            <inertia ixx="0.001" ixy="0.0" ixz="0.0" iyy="0.001" iyz="0.0" izz="0.001"/>
        </inertial>
    </link>

    <joint name="joint_right" type="continuous">
        <origin xyz="0.0 -0.115 0.0250" rpy="-1.5707 0.0 0.0"/>
        <parent link="base_link"/>
        <child link="right_wheel"/>
        <axis xyz="0.0 0.0 1.0"/>
        <limit effort="20" velocity="20.0"/>
    </joint>

    <link name="right_wheel">
        <visual>
            <origin xyz="0.0 0.0 0.0"/>
            <geometry>
                <cylinder length="0.0206" radius="0.035"/>
            </geometry>
            <material name="Green">
                <color rgba="0.0 1.0 0.0 1.0"/>
            </material>
        </visual>
        <collision>
            <origin xyz="0.0 0.0 0.0"/>
            <geometry>
                <cylinder length="0.0206" radius="0.035"/>
            </geometry>
        </collision>
        <inertial>
            <mass value="1.0"/>
            <inertia ixx="0.001" ixy="0.0" ixz="0.0" iyy="0.001" iyz="0.0" izz="0.001"/>
        </inertial>
    </link>

    <transmission name="tranmission_1">
        <type>transmission_interface/SimpleTransmission</type>
        <joint name="joint_left">
            <hardwareInterface>hardware_interface/VelocityJointInterface</hardwareInterface>
        </joint>
        <actuator name="motor1">
            <mechanicalReduction>1</mechanicalReduction>
        </actuator>
    </transmission>

    <transmission name="tranmission_2">
        <type>transmission_interface/SimpleTransmission</type>
        <joint name="joint_right">
            <hardwareInterface>hardware_interface/VelocityJointInterface</hardwareInterface>
        </joint>
        <actuator name="motor2">
            <mechanicalReduction>1</mechanicalReduction>
        </actuator>
    </transmission>

    <gazebo>
        <plugin name="gazebo_ros_control" filename="libgazebo_ros_control.so">
            <robotNamespace>/</robotNamespace>
        </plugin>
    </gazebo>

</robot>